Workbook
Name UPDATE: '[1]Data Sheet'!$E$1
Name UPDATE: '[1]Data Sheet'!$E$1
Name UPDATE: '[1]Data Sheet'!$E$1
Name UPDATE: 'Data Sheet'!$E$1

Sheet Title
A1: One Page Company Profile
A2: Historical Financial Statement Analysis
A3: Ratio Analysis
A4: Forecasting
A5: Common Size Statement
A6: WACC (Weighted Average Cost of Capital)
A7: Beta Regression
A8: Market Returns Analysis
A9: Intrinsic Growth Rate
A10: Discounted Cash Flow (DCF) Valuation
A11: Value at Risk (VAR)
A12: Monte Carlo Simulation
... A16: Altman's Z-Score

Sheet Data Sheet
A1: COMPANY NAME | B1: BRITANNIA INDUSTRIES LTD | E1: =IF(B2<>B3, "A NEW VERSION OF THE WORKSHEET IS AVAILABLE", "")
A2: LATEST VERSION | B2: 2.1 | E2: PLEASE DO NOT MAKE ANY CHANGES TO THIS SHEET
A3: CURRENT VERSION | B3: 2.1
A5: META
A6: Number of shares | B6: =IF(B9>0, B9/B8, 0) -> 24.077305
A7: Face Value | B7: 1
A8: Current Price | B8: 5250
A9: Market Capitalization | B9: 126405.85
A15: PROFIT & LOSS
A16: Report Date | B16: 42825 | C16: 43190 | D16: 43555 | E16: 43921 | F16: 44286 | G16: 44651 | H16: 45016 | I16: 45382 | J16: 45747 | K16: 46112
A17: Sales | B17: 9054.09 | C17: 9913.99 | D17: 11054.67 | E17: 11599.55 | F17: 13136.14 | G17: 14136.26 | H17: 16300.55 | I17: 16769.27 | J17: 17942.67 | K17: 19151.59
A18: Raw Material Cost | B18: 5642.88 | C18: 6100.8 | D18: 6616.64 | E18: 6874.9 | F18: 7663.22 | G18: 8835.56 | H18: 9663.83 | I18: 9488.37 | J18: 10668.8 | K18: 11155.25
A19: Change in Inventory | B19: 54.2 | C19: -6.3 | D19: 55.18 | E19: -52.57 | F19: 37.12 | G19: 75.26 | H19: 72.53 | I19: -3.66 | J19: 64.75 | K19: 22.37
A20: Power and Fuel | B20: 104.28 | C20: 128.83 | D20: 175.17 | E20: 177.7 | F20: 182.29 | G20: 217.68 | H20: 272.2 | I20: 327.25 | J20: 357.98 | K20: 342.87
A21: Other Mfr. Exp | B21: 509.93 | C21: 487.59 | D21: 621.32 | E21: 610.68 | F21: 672.21 | G21: 752.29 | H21: 893.75 | I21: 876.12 | J21: 954.03 | K21: 920.68
A22: Employee Cost | B22: 352.61 | C22: 401.6 | D22: 441.82 | E22: 486.69 | F22: 527.38 | G22: 542.26 | H22: 658.38 | I22: 708.7 | J22: 704.59 | K22: 823.8
A23: Selling and admin | B23: 915.01 | C23: 953.48 | D23: 1107.49 | E23: 1125.23 | F23: 1163.82 | G23: 1187.32 | H23: 1473.86 | I23: 1525.52 | J23: 1360 | K23: 1575.23
A24: Other Expenses | B24: 305.4 | C24: 333.92 | D24: 414.96 | E24: 428.6 | F24: 455.05 | G24: 475.1 | H24: 580.15 | I24: 673 | J24: 785.61 | K24: 841.79
A25: Other Income | B25: 150.54 | C25: 166.37 | D25: 206.45 | E25: 262.83 | F25: 313.07 | G25: 221.85 | H25: 596.87 | I25: 211.28 | J25: 202.3 | K25: 224.03
A26: Depreciation | B26: 119.27 | C26: 142.07 | D26: 161.88 | E26: 184.81 | F26: 197.85 | G26: 200.54 | H26: 225.91 | I26: 300.46 | J26: 313.34 | K26: 336.83
A27: Interest | B27: 5.45 | C27: 7.59 | D27: 9.09 | E27: 76.9 | F27: 110.9 | G27: 144.29 | H27: 169.1 | I27: 164 | J27: 138.8 | K27: 112.76
... A31: Dividend Amount | B31: 264 | C31: 300.12 | D31: 360.45 | E31: 841.75 | F31: 3794.18 | G31: 1361.08 | H31: 1734.48 | I31: 1770.62 | J31: 1806.75 | K31: 2180.14
A40: Quarters
A41: Report Date | B41: 45382 | C41: 45473 | D41: 45565 | E41: 45657 | F41: 45747 | G41: 45838 | H41: 45930 | I41: 46022 | J41: 46112 | K41: 46203
A42: Sales | B42: 4069.36 | C42: 4250.29 | D42: 4667.57 | E42: 4592.61 | F42: 4432.19 | G42: 4622.22 | H42: 4840.63 | I42: 4969.82 | J42: 4718.92 | K42: 4999.97
A43: Expenses | B43: 3285.71 | C43: 3497.28 | D43: 3887.56 | E43: 3749.75 | F43: 3631.67 | G43: 3870.02 | H43: 3889.39 | I43: 3992.49 | J43: 3885.35 | K43: 4161.65
A44: Other Income | B44: 57.34 | C44: 30.97 | D44: 45.85 | E44: 62.46 | F44: 63.02 | G44: 57.01 | H44: 52.11 | I44: 59.46 | J44: 55.45 | K44: 61.41
A45: Depreciation | B45: 79.93 | C45: 73.93 | D45: 76.07 | E45: 82.38 | F45: 80.96 | G45: 82.04 | H45: 85.05 | I45: 84.51 | J45: 85.23 | K45: 79.51
A46: Interest | B46: 26.44 | C46: 28.95 | D46: 34.64 | E46: 44.56 | F46: 30.65 | G46: 26.15 | H46: 34.68 | I46: 33.25 | J46: 18.68 | K46: 22.87
A47: Profit before tax | B47: 734.62 | C47: 681.1 | D47: 715.15 | E47: 778.38 | F47: 751.93 | G47: 701.02 | H47: 883.62 | I47: 919.03 | J47: 785.11 | K47: 797.35
A48: Tax | B48: 198.01 | C48: 176.22 | D48: 183.6 | E48: 196.08 | F48: 192.8 | G48: 180.89 | H48: 228.56 | I48: 236.89 | J48: 105.43 | K48: 203.97
A49: Net profit | B49: 538.28 | C49: 505.64 | D49: 531.45 | E49: 581.69 | F49: 559.95 | G49: 520.72 | H49: 654.47 | I49: 679.96 | J49: 678.34 | K49: 591.35
A50: Operating Profit | B50: 783.65 | C50: 753.01 | D50: 780.01 | E50: 842.86 | F50: 800.52 | G50: 752.2 | H50: 951.24 | I50: 977.33 | J50: 833.57 | K50: 838.32
A55: BALANCE SHEET
A56: Report Date | B56: 42825 | C56: 43190 | D56: 43555 | E56: 43921 | F56: 44286 | G56: 44651 | H56: 45016 | I56: 45382 | J56: 45747 | K56: 46112
A57: Equity Share Capital | B57: 24 | C57: 24.01 | D57: 24.03 | E57: 24.05 | F57: 24.09 | G57: 24.09 | H57: 24.09 | I57: 24.09 | J57: 24.09 | K57: 24.09
A58: Reserves | B58: 2672.42 | C58: 3382.22 | D58: 4229.22 | E58: 4378.78 | F58: 3523.57 | G58: 2534.01 | H58: 3510.18 | I58: 3917.43 | J58: 4331.63 | K58: 5082.47
A59: Borrowings | B59: 124.56 | C59: 200.7 | D59: 156.02 | E59: 1537.59 | F59: 2106.94 | G59: 2481.2 | H59: 2997.37 | I59: 2064.96 | J59: 1246.51 | K59: 1380.28
A60: Other Liabilities | B60: 1287.82 | C60: 1580.99 | D60: 1828.68 | E60: 1889.12 | F60: 2345.49 | G60: 2487.3 | H60: 2819.21 | I60: 3065.02 | J60: 3234.52 | K60: 3243.48
A61: Total | B61: 4108.8 | C61: 5187.92 | D61: 6237.95 | E61: 7829.54 | F61: 8000.09 | G61: 7526.6 | H61: 9350.85 | I61: 9071.5 | J61: 8836.75 | K61: 9730.32
...

Sheet Profit & Loss
A1: ='[1]Data Sheet'!B1 -> BRITANNIA INDUSTRIES LTD | H1: =UPDATE -> 0 | M1: SCREENER.IN
A3: Narration | B3: ='[1]Data Sheet'!B16 -> 42825 | C3: ='[1]Data Sheet'!C16 -> 43190 | D3: ='[1]Data Sheet'!D16 -> 43555 | E3: ='[1]Data Sheet'!E16 -> 43921 | F3: ='[1]Data Sheet'!F16 -> 44286 | G3: ='[1]Data Sheet'!G16 -> 44651 | H3: ='[1]Data Sheet'!H16 -> 45016 | I3: ='[1]Data Sheet'!I16 -> 45382 | ... K3: ='[1]Data Sheet'!K16 -> 46112 | L3: Trailing | M3: Best Case | N3: Worst Case
A4: Sales | B4: ='[1]Data Sheet'!B17 -> 9054.09 | C4: ='[1]Data Sheet'!C17 -> 9913.99 | D4: ='[1]Data Sheet'!D17 -> 11054.67 | E4: ='[1]Data Sheet'!E17 -> 11599.55 | F4: ='[1]Data Sheet'!F17 -> 13136.14 | G4: ='[1]Data Sheet'!G17 -> 14136.26 | H4: ='[1]Data Sheet'!H17 -> 16300.55 | I4: ='[1]Data Sheet'!I17 -> 16769.27 | ... K4: ='[1]Data Sheet'!K17 -> 19151.59 | L4: =SUM([1]Quarters!H4:K4) -> 0 | M4: =$K4+M23*K4 -> 20441.963 | N4: =$K4+N23*L4 -> 19151.59
A5: Expenses | B5: =SUM('[1]Data Sheet'!B18,'[1]Data Sheet'!B20:B24, -1*'[1]Data Sheet'!B19) -> 7775.91 | C5: =SUM('[1]Data Sheet'!C18,'[1]Data Sheet'!C20:C24, -1*'[1]Data Sheet'!C19) -> 8412.52 | D5: =SUM('[1]Data Sheet'!D18,'[1]Data Sheet'!D20:D24, -1*'[1]Data Sheet'!D19) -> 9322.22 | E5: =SUM('[1]Data Sheet'!E18,'[1]Data Sheet'!E20:E24, -1*'[1]Data Sheet'!E19) -> 9756.37 | F5: =SUM('[1]Data Sheet'!F18,'[1]Data Sheet'!F20:F24, -1*'[1]Data Sheet'!F19) -> 10626.85 | G5: =SUM('[1]Data Sheet'!G18,'[1]Data Sheet'!G20:G24, -1*'[1]Data Sheet'!G19) -> 11934.95 | H5: =SUM('[1]Data Sheet'!H18,'[1]Data Sheet'!H20:H24, -1*'[1]Data Sheet'!H19) -> 13469.64 | I5: =SUM('[1]Data Sheet'!I18,'[1]Data Sheet'!I20:I24, -1*'[1]Data Sheet'!I19) -> 13602.62 | ... K5: =SUM('[1]Data Sheet'!K18,'[1]Data Sheet'!K20:K24, -1*'[1]Data Sheet'!K19) -> 15637.25 | L5: =SUM([1]Quarters!H5:K5) -> 0 | M5: =M4-M6 -> 16700.942 | N5: =N4-N6 -> 19151.59
A6: Operating Profit | B6: =B4-B5 -> 1278.18 | C6: =C4-C5 -> 1501.47 | D6: =D4-D5 -> 1732.45 | E6: =E4-E5 -> 1843.18 | F6: =F4-F5 -> 2509.29 | G6: =G4-G5 -> 2201.31 | H6: =H4-H5 -> 2830.91 | I6: =I4-I5 -> 3166.65 | ... K6: =K4-K5 -> 3514.34 | L6: =SUM([1]Quarters!H6:K6) -> 0 | M6: =M4*M24 -> 3741.0212 | N6: =N4*N24 -> 0
A7: Other Income | B7: ='[1]Data Sheet'!B25 -> 150.54 | C7: ='[1]Data Sheet'!C25 -> 166.37 | D7: ='[1]Data Sheet'!D25 -> 206.45 | E7: ='[1]Data Sheet'!E25 -> 262.83 | F7: ='[1]Data Sheet'!F25 -> 313.07 | G7: ='[1]Data Sheet'!G25 -> 221.85 | H7: ='[1]Data Sheet'!H25 -> 596.87 | I7: ='[1]Data Sheet'!I25 -> 211.28 | ... K7: ='[1]Data Sheet'!K25 -> 224.03 | L7: =SUM([1]Quarters!H7:K7) -> 0 | M7: 0 | N7: 0
A8: Depreciation | B8: ='[1]Data Sheet'!B26 -> 119.27 | C8: ='[1]Data Sheet'!C26 -> 142.07 | D8: ='[1]Data Sheet'!D26 -> 161.88 | E8: ='[1]Data Sheet'!E26 -> 184.81 | F8: ='[1]Data Sheet'!F26 -> 197.85 | G8: ='[1]Data Sheet'!G26 -> 200.54 | H8: ='[1]Data Sheet'!H26 -> 225.91 | I8: ='[1]Data Sheet'!I26 -> 300.46 | ... K8: ='[1]Data Sheet'!K26 -> 336.83 | L8: =SUM([1]Quarters!H8:K8) -> 0 | M8: =+$L8 -> 0 | N8: =+$L8 -> 0
A9: Interest | B9: ='[1]Data Sheet'!B27 -> 5.45 | C9: ='[1]Data Sheet'!C27 -> 7.59 | D9: ='[1]Data Sheet'!D27 -> 9.09 | E9: ='[1]Data Sheet'!E27 -> 76.9 | F9: ='[1]Data Sheet'!F27 -> 110.9 | G9: ='[1]Data Sheet'!G27 -> 144.29 | H9: ='[1]Data Sheet'!H27 -> 169.1 | I9: ='[1]Data Sheet'!I27 -> 164 | ... K9: ='[1]Data Sheet'!K27 -> 112.76 | L9: =SUM([1]Quarters!H9:K9) -> 0 | M9: =+$L9 -> 0 | N9: =+$L9 -> 0
A10: Profit before tax | B10: ='[1]Data Sheet'!B28 -> 1304 | C10: ='[1]Data Sheet'!C28 -> 1518.18 | D10: ='[1]Data Sheet'!D28 -> 1767.93 | E10: ='[1]Data Sheet'!E28 -> 1844.3 | F10: ='[1]Data Sheet'!F28 -> 2513.61 | G10: ='[1]Data Sheet'!G28 -> 2078.33 | H10: ='[1]Data Sheet'!H28 -> 3032.77 | I10: ='[1]Data Sheet'!I28 -> 2913.47 | ... K10: ='[1]Data Sheet'!K28 -> 3288.78 | L10: =SUM([1]Quarters!H10:K10) -> 0 | M10: =M6+M7-SUM(M8:M9) -> 3741.0212 | N10: =N6+N7-SUM(N8:N9) -> 0
A11: Tax | B11: ='[1]Data Sheet'!B29 -> 419.67 | C11: ='[1]Data Sheet'!C29 -> 514.22 | D11: ='[1]Data Sheet'!D29 -> 612.47 | E11: ='[1]Data Sheet'!E29 -> 450.7 | F11: ='[1]Data Sheet'!F29 -> 663.02 | G11: ='[1]Data Sheet'!G29 -> 562.35 | H11: ='[1]Data Sheet'!H29 -> 716.45 | I11: ='[1]Data Sheet'!I29 -> 779.25 | ... K11: ='[1]Data Sheet'!K29 -> 751.77 | L11: =SUM([1]Quarters!H11:K11) -> 0 | M11: =IF($L10>0,$L11/$L10,0) -> 0 | N11: =IF($L10>0,$L11/$L10,0) -> 0
A12: Net profit | B12: ='[1]Data Sheet'!B30 -> 884.47 | C12: ='[1]Data Sheet'!C30 -> 1004.23 | D12: ='[1]Data Sheet'!D30 -> 1159.12 | E12: ='[1]Data Sheet'!E30 -> 1402.63 | F12: ='[1]Data Sheet'!F30 -> 1863.9 | G12: ='[1]Data Sheet'!G30 -> 1524.82 | H12: ='[1]Data Sheet'!H30 -> 2321.77 | I12: ='[1]Data Sheet'!I30 -> 2139.81 | ... K12: ='[1]Data Sheet'!K30 -> 2533.49 | L12: =SUM([1]Quarters!H12:K12) -> 0 | M12: =M10-M11*M10 -> 3741.0212 | N12: =N10-N11*N10 -> 0
A13: EPS | B13: =IF('[1]Data Sheet'!B93>0,B12/'[1]Data Sheet'!B93,0) -> 36.852917 | C13: =IF('[1]Data Sheet'!C93>0,C12/'[1]Data Sheet'!C93,0) -> 41.825489 | D13: =IF('[1]Data Sheet'!D93>0,D12/'[1]Data Sheet'!D93,0) -> 48.236371 | E13: =IF('[1]Data Sheet'!E93>0,E12/'[1]Data Sheet'!E93,0) -> 58.321414 | F13: =IF('[1]Data Sheet'!F93>0,F12/'[1]Data Sheet'!F93,0) -> 77.372354 | G13: =IF('[1]Data Sheet'!G93>0,G12/'[1]Data Sheet'!G93,0) -> 63.296804 | H13: =IF('[1]Data Sheet'!H93>0,H12/'[1]Data Sheet'!H93,0) -> 96.378995 | I13: =IF('[1]Data Sheet'!I93>0,I12/'[1]Data Sheet'!I93,0) -> 88.825654 | ... K13: =IF('[1]Data Sheet'!K93>0,K12/'[1]Data Sheet'!K93,0) -> 105.1677 | L13: =IF('[1]Data Sheet'!$B6>0,'Profit & Loss'!L12/'[1]Data Sheet'!$B6,0) -> 0 | M13: =IF('[1]Data Sheet'!$B6>0,'Profit & Loss'!M12/'[1]Data Sheet'!$B6,0) -> 0 | N13: =IF('[1]Data Sheet'!$B6>0,'Profit & Loss'!N12/'[1]Data Sheet'!$B6,0) -> 0
A14: Price to earning | B14: =IF(B15>0,B15/B13,"") -> 45.776567 | C14: =IF(C15>0,C15/C13,"") -> 59.420703 | D14: =IF(D15>0,D15/D13,"") -> 63.966255 | E14: =IF(E15>0,E15/E13,"") -> 46.105707 | F14: =IF(F15>0,F15/F13,"") -> 46.852006 | G14: =IF(G15>0,G15/G13,"") -> 50.656586 | H14: =IF(H15>0,H15/H13,"") -> 44.845352 | I14: =IF(I15>0,I15/I13,"") -> 55.290896 | ... K14: =IF(K15>0,K15/K13,"") -> 51.56526 | L14: =IF(L13>0,L15/L13,0) -> 0 | M14: =M25 -> 53.814322 | N14: =N25 -> 0
A15: Price | B15: ='[1]Data Sheet'!B90 -> 1687 | C15: ='[1]Data Sheet'!C90 -> 2485.3 | D15: ='[1]Data Sheet'!D90 -> 3085.5 | E15: ='[1]Data Sheet'!E90 -> 2688.95 | F15: ='[1]Data Sheet'!F90 -> 3625.05 | G15: ='[1]Data Sheet'!G90 -> 3206.4 | H15: ='[1]Data Sheet'!H90 -> 4322.15 | I15: ='[1]Data Sheet'!I90 -> 4911.25 | ... K15: ='[1]Data Sheet'!K90 -> 5423 | L15: ='[1]Data Sheet'!B8 -> 5250 | M15: =M13*M14 -> 0 | N15: =N13*N14 -> 0
A17: RATIOS:
A18: Dividend Payout | B18: =IF('[1]Data Sheet'!B30>0, '[1]Data Sheet'!B31/'[1]Data Sheet'!B30, 0) -> 0.29848384 | C18: =IF('[1]Data Sheet'!C30>0, '[1]Data Sheet'!C31/'[1]Data Sheet'!C30, 0) -> 0.29885584 | D18: =IF('[1]Data Sheet'!D30>0, '[1]Data Sheet'!D31/'[1]Data Sheet'!D30, 0) -> 0.31096867 | E18: =IF('[1]Data Sheet'!E30>0, '[1]Data Sheet'!E31/'[1]Data Sheet'!E30, 0) -> 0.60012263 | F18: =IF('[1]Data Sheet'!F30>0, '[1]Data Sheet'!F31/'[1]Data Sheet'!F30, 0) -> 2.0356135 | G18: =IF('[1]Data Sheet'!G30>0, '[1]Data Sheet'!G31/'[1]Data Sheet'!G30, 0) -> 0.89261683 | H18: =IF('[1]Data Sheet'!H30>0, '[1]Data Sheet'!H31/'[1]Data Sheet'!H30, 0) -> 0.74705074 | I18: =IF('[1]Data Sheet'!I30>0, '[1]Data Sheet'!I31/'[1]Data Sheet'!I30, 0) -> 0.82746599 | ... K18: =IF('[1]Data Sheet'!K30>0, '[1]Data Sheet'!K31/'[1]Data Sheet'!K30, 0) -> 0.86052836
A19: OPM | B19: =IF(B6>0,B6/B4,0) -> 0.14117156 | C19: =IF(C6>0,C6/C4,0) -> 0.15144962 | D19: =IF(D6>0,D6/D4,0) -> 0.15671657 | E19: =IF(E6>0,E6/E4,0) -> 0.15890099 | F19: =IF(F6>0,F6/F4,0) -> 0.19102187 | G19: =IF(G6>0,G6/G4,0) -> 0.15572082 | H19: =IF(H6>0,H6/H4,0) -> 0.1736696 | I19: =IF(I6>0,I6/I4,0) -> 0.18883648 | ... L19: =IF(L6>0,L6/L4,0) -> 0
G22: TRENDS: | H22: 10 YEARS | I22: 7 YEARS | J22: 5 YEARS | K22: 3 YEARS | L22: RECENT | M22: BEST | N22: WORST
G23: Sales Growth | H23: =IF(B4=0,"",POWER($K4/B4,1/9)-1) -> 0.086803715 | I23: =IF(D4=0,"",POWER($K4/D4,1/7)-1) -> 0.08166842 | J23: =IF(F4=0,"",POWER($K4/F4,1/5)-1) -> 0.078319387 | K23: =IF(H4=0,"",POWER($K4/H4, 1/3)-1) -> 0.055198566 | L23: =IF(ISERROR(MAX(IF(J4=0,"",(K4-J4)/J4),IF(K4=0,"",(L4-K4)/K4))),"",MAX(IF(J4=0,"",(K4-J4)/J4),IF(K4=0,"",(L4-K4)/K4))) -> 0.067376817 | M23: =MAX(K23:L23) -> 0.067376817 | N23: =MIN(H23:L23) -> 0.055198566
G24: OPM | H24: =IF(SUM(B4:$K$4)=0,"",SUMPRODUCT(B19:$K$19,B4:$K$4)/SUM(B4:$K$4)) -> 0.17082122 | I24: =IF(SUM(E4:$K$4)=0,"",SUMPRODUCT(E19:$K$19,E4:$K$4)/SUM(E4:$K$4)) -> 0.1764746 | J24: =IF(SUM(G4:$K$4)=0,"",SUMPRODUCT(G19:$K$19,G4:$K$4)/SUM(G4:$K$4)) -> 0.17662586 | K24: =IF(SUM(I4:$K$4)=0, "", SUMPRODUCT(I19:$K$19,I4:$K$4)/SUM(I4:$K$4)) -> 0.18300694 | L24: =L19 -> 0 | M24: =MAX(K24:L24) -> 0.18300694 | N24: =MIN(H24:L24) -> 0
G25: Price to Earning | H25: =IF(ISERROR(AVERAGEIF(B14:$L14,">0")),"",AVERAGEIF(B14:$L14,">0")) -> 51.906614 | I25: =IF(ISERROR(AVERAGEIF(E14:$L14,">0")),"",AVERAGEIF(E14:$L14,">0")) -> 49.986088 | J25: =IF(ISERROR(AVERAGEIF(G14:$L14,">0")),"",AVERAGEIF(G14:$L14,">0")) -> 51.388981 | K25: =IF(ISERROR(AVERAGEIF(I14:$L14,">0")),"",AVERAGEIF(I14:$L14,">0")) -> 53.814322 | L25: =L14 -> 0 | M25: =MAX(K25:L25) -> 53.814322 | N25: =MIN(H25:L25) -> 0
A28: Sales growth Y-O-Y | C28: =C4/B4-1 -> 0.094973653 | D28: =D4/C4-1 -> 0.11505761 | E28: =E4/D4-1 -> 0.049289576 | F28: =F4/E4-1 -> 0.13246979 | G28: =G4/F4-1 -> 0.076134999 | H28: =H4/G4-1 -> 0.15310202 | I28: =I4/H4-1 -> 0.028754858 | J28: =J4/I4-1 -> 0.069973231 | K28: =K4/J4-1 -> 0.067376817
A29: Market Capitalization | B29: ='Data Sheet'!B93*'Data Sheet'!B90 -> 40488 | C29: ='Data Sheet'!C93*'Data Sheet'!C90 -> 59672.053 | D29: ='Data Sheet'!D93*'Data Sheet'!D90 -> 74144.565 | E29: ='Data Sheet'!E93*'Data Sheet'!E90 -> 64669.247 | F29: ='Data Sheet'!F93*'Data Sheet'!F90 -> 87327.455 | G29: ='Data Sheet'!G93*'Data Sheet'!G90 -> 77242.176 | H29: ='Data Sheet'!H93*'Data Sheet'!H90 -> 104120.59 | I29: ='Data Sheet'!I93*'Data Sheet'!I90 -> 118312.01 | ... K29: ='Data Sheet'!K93*'Data Sheet'!K90 -> 130640.07
A30: Debt | B30: ='Data Sheet'!B59 -> 124.56 | C30: ='Data Sheet'!C59 -> 200.7 | D30: ='Data Sheet'!D59 -> 156.02 | E30: ='Data Sheet'!E59 -> 1537.59 | F30: ='Data Sheet'!F59 -> 2106.94 | G30: ='Data Sheet'!G59 -> 2481.2 | H30: ='Data Sheet'!H59 -> 2997.37 | I30: ='Data Sheet'!I59 -> 2064.96 | ... K30: ='Data Sheet'!K59 -> 1380.28
A31: Cash | B31: ='Data Sheet'!B69 -> 120.76 | C31: ='Data Sheet'!C69 -> 186.42 | D31: ='Data Sheet'!D69 -> 109.82 | E31: ='Data Sheet'!E69 -> 122.85 | F31: ='Data Sheet'!F69 -> 211.34 | G31: ='Data Sheet'!G69 -> 184.9 | H31: ='Data Sheet'!H69 -> 197.98 | I31: ='Data Sheet'!I69 -> 446.35 | ... K31: ='Data Sheet'!K69 -> 352.44
A32: EV | B32: =B29+B30-B31 -> 40491.8 | C32: =C29+C30-C31 -> 59686.333 | D32: =D29+D30-D31 -> 74190.765 | E32: =E29+E30-E31 -> 66083.987 | F32: =F29+F30-F31 -> 89223.055 | G32: =G29+G30-G31 -> 79538.476 | H32: =H29+H30-H31 -> 106919.98 | I32: =I29+I30-I31 -> 119930.62 | ... K32: =K29+K30-K31 -> 131667.91
A34: EBITDA | B34: ='Historical FS'!C24 -> 1278.18 | C34: ='Historical FS'!D24 -> 1501.47 | D34: ='Historical FS'!E24 -> 1732.45 | E34: ='Historical FS'!F24 -> 1843.18 | F34: ='Historical FS'!G24 -> 2509.29 | G34: ='Historical FS'!H24 -> 2201.31 | H34: ='Historical FS'!I24 -> 2830.91 | I34: ='Historical FS'!J24 -> 3166.65 | ... K34: ='Historical FS'!L24 -> 3514.34
A35: EV/EBITDA | B35: =B32/B34 -> 31.679263 | C35: =C32/C34 -> 39.751932 | D35: =D32/D34 -> 42.824188 | E35: =E32/E34 -> 35.853247 | F35: =F32/F34 -> 35.557092 | G35: =G32/G34 -> 36.132338 | H35: =H32/H34 -> 37.768768 | I35: =I32/I34 -> 37.873027 | ... K35: =K32/K34 -> 37.4659
A36: EV/Sales | B36: =B32/B4 -> 4.4722109 | C36: =C32/C4 -> 6.0204149 | D36: =D32/D4 -> 6.71126 | E36: =E32/E4 -> 5.6971165 | F36: =F32/F4 -> 6.7921821 | G36: =G32/G4 -> 5.6265572 | H36: =H32/H4 -> 6.5592869 | I36: =I32/I4 -> 7.1518094 | ... K36: =K32/K4 -> 6.8750381
A38: Book Value of Equity | B38: ='Balance Sheet'!B4+'Balance Sheet'!B5 -> 2696.42 | C38: ='Balance Sheet'!C4+'Balance Sheet'!C5 -> 3406.23 | D38: ='Balance Sheet'!D4+'Balance Sheet'!D5 -> 4253.25 | E38: ='Balance Sheet'!E4+'Balance Sheet'!E5 -> 4402.83 | F38: ='Balance Sheet'!F4+'Balance Sheet'!F5 -> 3547.66 | G38: ='Balance Sheet'!G4+'Balance Sheet'!G5 -> 2558.1 | H38: ='Balance Sheet'!H4+'Balance Sheet'!H5 -> 3534.27 | I38: ='Balance Sheet'!I4+'Balance Sheet'!I5 -> 3941.52 | ... K38: ='Balance Sheet'!K4+'Balance Sheet'!K5 -> 5106.56
A39: Price/Book Value | B39: =B29/B38 -> 15.015465 | C39: =C29/C38 -> 17.518504 | D39: =D29/D38 -> 17.432449 | E39: =E29/E38 -> 14.688109 | F39: =F29/F38 -> 24.615508 | G39: =G29/G38 -> 30.195135 | H39: =H29/H38 -> 29.460283 | I39: =I29/I38 -> 30.016849 | ... K39: =K29/K38 -> 25.582794

Sheet Balance Sheet
A1: ='[1]Profit & Loss'!A1 -> 0 | E1: =UPDATE -> 0 | J1: SCREENER.IN
A3: Narration | B3: ='[1]Data Sheet'!B56 -> 42825 | C3: ='[1]Data Sheet'!C56 -> 43190 | D3: ='[1]Data Sheet'!D56 -> 43555 | E3: ='[1]Data Sheet'!E56 -> 43921 | F3: ='[1]Data Sheet'!F56 -> 44286 | G3: ='[1]Data Sheet'!G56 -> 44651 | H3: ='[1]Data Sheet'!H56 -> 45016 | I3: ='[1]Data Sheet'!I56 -> 45382 | ... K3: ='[1]Data Sheet'!K56 -> 46112
A4: Equity Share Capital | B4: ='[1]Data Sheet'!B57 -> 24 | C4: ='[1]Data Sheet'!C57 -> 24.01 | D4: ='[1]Data Sheet'!D57 -> 24.03 | E4: ='[1]Data Sheet'!E57 -> 24.05 | F4: ='[1]Data Sheet'!F57 -> 24.09 | G4: ='[1]Data Sheet'!G57 -> 24.09 | H4: ='[1]Data Sheet'!H57 -> 24.09 | I4: ='[1]Data Sheet'!I57 -> 24.09 | ... K4: ='[1]Data Sheet'!K57 -> 24.09
A5: Reserves | B5: ='[1]Data Sheet'!B58 -> 2672.42 | C5: ='[1]Data Sheet'!C58 -> 3382.22 | D5: ='[1]Data Sheet'!D58 -> 4229.22 | E5: ='[1]Data Sheet'!E58 -> 4378.78 | F5: ='[1]Data Sheet'!F58 -> 3523.57 | G5: ='[1]Data Sheet'!G58 -> 2534.01 | H5: ='[1]Data Sheet'!H58 -> 3510.18 | I5: ='[1]Data Sheet'!I58 -> 3917.43 | ... K5: ='[1]Data Sheet'!K58 -> 5082.47
A6: Borrowings | B6: ='[1]Data Sheet'!B59 -> 124.56 | C6: ='[1]Data Sheet'!C59 -> 200.7 | D6: ='[1]Data Sheet'!D59 -> 156.02 | E6: ='[1]Data Sheet'!E59 -> 1537.59 | F6: ='[1]Data Sheet'!F59 -> 2106.94 | G6: ='[1]Data Sheet'!G59 -> 2481.2 | H6: ='[1]Data Sheet'!H59 -> 2997.37 | I6: ='[1]Data Sheet'!I59 -> 2064.96 | ... K6: ='[1]Data Sheet'!K59 -> 1380.28
A7: Other Liabilities | B7: ='[1]Data Sheet'!B60 -> 1287.82 | C7: ='[1]Data Sheet'!C60 -> 1580.99 | D7: ='[1]Data Sheet'!D60 -> 1828.68 | E7: ='[1]Data Sheet'!E60 -> 1889.12 | F7: ='[1]Data Sheet'!F60 -> 2345.49 | G7: ='[1]Data Sheet'!G60 -> 2487.3 | H7: ='[1]Data Sheet'!H60 -> 2819.21 | I7: ='[1]Data Sheet'!I60 -> 3065.02 | ... K7: ='[1]Data Sheet'!K60 -> 3243.48
A8: Total | B8: ='[1]Data Sheet'!B61 -> 4108.8 | C8: ='[1]Data Sheet'!C61 -> 5187.92 | D8: ='[1]Data Sheet'!D61 -> 6237.95 | E8: ='[1]Data Sheet'!E61 -> 7829.54 | F8: ='[1]Data Sheet'!F61 -> 8000.09 | G8: ='[1]Data Sheet'!G61 -> 7526.6 | H8: ='[1]Data Sheet'!H61 -> 9350.85 | I8: ='[1]Data Sheet'!I61 -> 9071.5 | ... K8: ='[1]Data Sheet'!K61 -> 9730.32
A10: Net Block | B10: ='[1]Data Sheet'!B62 -> 1159.99 | C10: ='[1]Data Sheet'!C62 -> 1345.6 | D10: ='[1]Data Sheet'!D62 -> 1688.3 | E10: ='[1]Data Sheet'!E62 -> 1878.18 | F10: ='[1]Data Sheet'!F62 -> 1792.95 | G10: ='[1]Data Sheet'!G62 -> 1753.21 | H10: ='[1]Data Sheet'!H62 -> 2655.22 | I10: ='[1]Data Sheet'!I62 -> 2771.14 | ... K10: ='[1]Data Sheet'!K62 -> 2849.92
A11: Capital Work in Progress | B11: ='[1]Data Sheet'!B63 -> 30.07 | C11: ='[1]Data Sheet'!C63 -> 202.82 | D11: ='[1]Data Sheet'!D63 -> 101.24 | E11: ='[1]Data Sheet'!E63 -> 39.55 | F11: ='[1]Data Sheet'!F63 -> 116.52 | G11: ='[1]Data Sheet'!G63 -> 535.68 | H11: ='[1]Data Sheet'!H63 -> 105 | I11: ='[1]Data Sheet'!I63 -> 187.54 | ... K11: ='[1]Data Sheet'!K63 -> 39.04
A12: Investments | B12: ='[1]Data Sheet'!B64 -> 486.85 | C12: ='[1]Data Sheet'!C64 -> 1079.28 | D12: ='[1]Data Sheet'!D64 -> 1476.28 | E12: ='[1]Data Sheet'!E64 -> 2893.23 | F12: ='[1]Data Sheet'!F64 -> 2780.69 | G12: ='[1]Data Sheet'!G64 -> 1762.37 | H12: ='[1]Data Sheet'!H64 -> 3324.24 | I12: ='[1]Data Sheet'!I64 -> 2766.72 | ... K12: ='[1]Data Sheet'!K64 -> 3609.76
A13: Other Assets | B13: ='[1]Data Sheet'!B65 -> 2431.89 | C13: ='[1]Data Sheet'!C65 -> 2560.22 | D13: ='[1]Data Sheet'!D65 -> 2972.13 | E13: ='[1]Data Sheet'!E65 -> 3018.58 | F13: ='[1]Data Sheet'!F65 -> 3309.93 | G13: ='[1]Data Sheet'!G65 -> 3475.34 | H13: ='[1]Data Sheet'!H65 -> 3266.39 | I13: ='[1]Data Sheet'!I65 -> 3346.1 | ... K13: ='[1]Data Sheet'!K65 -> 3231.6
A14: Total | B14: ='[1]Data Sheet'!B66 -> 4108.8 | C14: ='[1]Data Sheet'!C66 -> 5187.92 | D14: ='[1]Data Sheet'!D66 -> 6237.95 | E14: ='[1]Data Sheet'!E66 -> 7829.54 | F14: ='[1]Data Sheet'!F66 -> 8000.09 | G14: ='[1]Data Sheet'!G66 -> 7526.6 | H14: ='[1]Data Sheet'!H66 -> 9350.85 | I14: ='[1]Data Sheet'!I66 -> 9071.5 | ... K14: ='[1]Data Sheet'!K66 -> 9730.32
A16: Working Capital | B16: =B13-B7 -> 1144.07 | C16: =C13-C7 -> 979.23 | D16: =D13-D7 -> 1143.45 | E16: =E13-E7 -> 1129.46 | F16: =F13-F7 -> 964.44 | G16: =G13-G7 -> 988.04 | H16: =H13-H7 -> 447.18 | I16: =I13-I7 -> 281.08 | ... K16: =K13-K7 -> -11.88
A17: Debtors | B17: ='[1]Data Sheet'!B67 -> 179.16 | C17: ='[1]Data Sheet'!C67 -> 304.6 | D17: ='[1]Data Sheet'!D67 -> 394.24 | E17: ='[1]Data Sheet'!E67 -> 320.36 | F17: ='[1]Data Sheet'!F67 -> 257.27 | G17: ='[1]Data Sheet'!G67 -> 331.93 | H17: ='[1]Data Sheet'!H67 -> 328.94 | I17: ='[1]Data Sheet'!I67 -> 393.33 | ... K17: ='[1]Data Sheet'!K67 -> 469.21
A18: Inventory | B18: ='[1]Data Sheet'!B68 -> 661.45 | C18: ='[1]Data Sheet'!C68 -> 652.79 | D18: ='[1]Data Sheet'!D68 -> 781.38 | E18: ='[1]Data Sheet'!E68 -> 740.96 | F18: ='[1]Data Sheet'!F68 -> 1091.49 | G18: ='[1]Data Sheet'!G68 -> 1367.49 | H18: ='[1]Data Sheet'!H68 -> 1193.26 | I18: ='[1]Data Sheet'!I68 -> 1181.22 | ... K18: ='[1]Data Sheet'!K68 -> 1345.93
A20: Debtor Days | B20: =IF('[1]Profit & Loss'!B4>0,'Balance Sheet'!B17/('[1]Profit & Loss'!B4/365),0) -> 0 | C20: =IF('[1]Profit & Loss'!C4>0,'Balance Sheet'!C17/('[1]Profit & Loss'!C4/365),0) -> 0 | D20: =IF('[1]Profit & Loss'!D4>0,'Balance Sheet'!D17/('[1]Profit & Loss'!D4/365),0) -> 0 | E20: =IF('[1]Profit & Loss'!E4>0,'Balance Sheet'!E17/('[1]Profit & Loss'!E4/365),0) -> 0 | F20: =IF('[1]Profit & Loss'!F4>0,'Balance Sheet'!F17/('[1]Profit & Loss'!F4/365),0) -> 0 | G20: =IF('[1]Profit & Loss'!G4>0,'Balance Sheet'!G17/('[1]Profit & Loss'!G4/365),0) -> 0 | H20: =IF('[1]Profit & Loss'!H4>0,'Balance Sheet'!H17/('[1]Profit & Loss'!H4/365),0) -> 0 | I20: =IF('[1]Profit & Loss'!I4>0,'Balance Sheet'!I17/('[1]Profit & Loss'!I4/365),0) -> 0 | ... K20: =IF('[1]Profit & Loss'!K4>0,'Balance Sheet'!K17/('[1]Profit & Loss'!K4/365),0) -> 0
A21: Inventory Turnover | B21: =IF('Balance Sheet'!B18>0,'[1]Profit & Loss'!B4/'Balance Sheet'!B18,0) -> 0 | C21: =IF('Balance Sheet'!C18>0,'[1]Profit & Loss'!C4/'Balance Sheet'!C18,0) -> 0 | D21: =IF('Balance Sheet'!D18>0,'[1]Profit & Loss'!D4/'Balance Sheet'!D18,0) -> 0 | E21: =IF('Balance Sheet'!E18>0,'[1]Profit & Loss'!E4/'Balance Sheet'!E18,0) -> 0 | F21: =IF('Balance Sheet'!F18>0,'[1]Profit & Loss'!F4/'Balance Sheet'!F18,0) -> 0 | G21: =IF('Balance Sheet'!G18>0,'[1]Profit & Loss'!G4/'Balance Sheet'!G18,0) -> 0 | H21: =IF('Balance Sheet'!H18>0,'[1]Profit & Loss'!H4/'Balance Sheet'!H18,0) -> 0 | I21: =IF('Balance Sheet'!I18>0,'[1]Profit & Loss'!I4/'Balance Sheet'!I18,0) -> 0 | ... K21: =IF('Balance Sheet'!K18>0,'[1]Profit & Loss'!K4/'Balance Sheet'!K18,0) -> 0
A23: Return on Equity | B23: =IF(SUM('Balance Sheet'!B4:B5)>0,'[1]Profit & Loss'!B12/SUM('Balance Sheet'!B4:B5),"") -> 0 | C23: =IF(SUM('Balance Sheet'!C4:C5)>0,'[1]Profit & Loss'!C12/SUM('Balance Sheet'!C4:C5),"") -> 0 | D23: =IF(SUM('Balance Sheet'!D4:D5)>0,'[1]Profit & Loss'!D12/SUM('Balance Sheet'!D4:D5),"") -> 0 | E23: =IF(SUM('Balance Sheet'!E4:E5)>0,'[1]Profit & Loss'!E12/SUM('Balance Sheet'!E4:E5),"") -> 0 | F23: =IF(SUM('Balance Sheet'!F4:F5)>0,'[1]Profit & Loss'!F12/SUM('Balance Sheet'!F4:F5),"") -> 0 | G23: =IF(SUM('Balance Sheet'!G4:G5)>0,'[1]Profit & Loss'!G12/SUM('Balance Sheet'!G4:G5),"") -> 0 | H23: =IF(SUM('Balance Sheet'!H4:H5)>0,'[1]Profit & Loss'!H12/SUM('Balance Sheet'!H4:H5),"") -> 0 | I23: =IF(SUM('Balance Sheet'!I4:I5)>0,'[1]Profit & Loss'!I12/SUM('Balance Sheet'!I4:I5),"") -> 0 | ... K23: =IF(SUM('Balance Sheet'!K4:K5)>0,'[1]Profit & Loss'!K12/SUM('Balance Sheet'!K4:K5),"") -> 0
A24: Return on Capital Emp | C24: =IF((B4+B5+B6+C4+C5+C6)>0,('[1]Profit & Loss'!C10+'[1]Profit & Loss'!C9)*2/(B4+B5+B6+C4+C5+C6),"") -> 0 | D24: =IF((C4+C5+C6+D4+D5+D6)>0,('[1]Profit & Loss'!D10+'[1]Profit & Loss'!D9)*2/(C4+C5+C6+D4+D5+D6),"") -> 0 | E24: =IF((D4+D5+D6+E4+E5+E6)>0,('[1]Profit & Loss'!E10+'[1]Profit & Loss'!E9)*2/(D4+D5+D6+E4+E5+E6),"") -> 0 | F24: =IF((E4+E5+E6+F4+F5+F6)>0,('[1]Profit & Loss'!F10+'[1]Profit & Loss'!F9)*2/(E4+E5+E6+F4+F5+F6),"") -> 0 | G24: =IF((F4+F5+F6+G4+G5+G6)>0,('[1]Profit & Loss'!G10+'[1]Profit & Loss'!G9)*2/(F4+F5+F6+G4+G5+G6),"") -> 0 | H24: =IF((G4+G5+G6+H4+H5+H6)>0,('[1]Profit & Loss'!H10+'[1]Profit & Loss'!H9)*2/(G4+G5+G6+H4+H5+H6),"") -> 0 | I24: =IF((H4+H5+H6+I4+I5+I6)>0,('[1]Profit & Loss'!I10+'[1]Profit & Loss'!I9)*2/(H4+H5+H6+I4+I5+I6),"") -> 0 | J24: =IF((I4+I5+I6+J4+J5+J6)>0,('[1]Profit & Loss'!J10+'[1]Profit & Loss'!J9)*2/(I4+I5+I6+J4+J5+J6),"") -> 0 | K24: =IF((J4+J5+J6+K4+K5+K6)>0,('[1]Profit & Loss'!K10+'[1]Profit & Loss'!K9)*2/(J4+J5+J6+K4+K5+K6),"") -> 0

Sheet Cash Flow
A1: ='[1]Balance Sheet'!A1 -> 0 | E1: =UPDATE -> 0 | J1: SCREENER.IN
A3: Narration | B3: ='[1]Data Sheet'!B81 -> 42825 | C3: ='[1]Data Sheet'!C81 -> 43190 | D3: ='[1]Data Sheet'!D81 -> 43555 | E3: ='[1]Data Sheet'!E81 -> 43921 | F3: ='[1]Data Sheet'!F81 -> 44286 | G3: ='[1]Data Sheet'!G81 -> 44651 | H3: ='[1]Data Sheet'!H81 -> 45016 | I3: ='[1]Data Sheet'!I81 -> 45382 | ... K3: ='[1]Data Sheet'!K81 -> 46112
A4: Cash from Operating Activity | B4: ='[1]Data Sheet'!B82 -> 441.28 | C4: ='[1]Data Sheet'!C82 -> 1248.77 | D4: ='[1]Data Sheet'!D82 -> 1155.78 | E4: ='[1]Data Sheet'!E82 -> 1484.53 | F4: ='[1]Data Sheet'!F82 -> 1851.07 | G4: ='[1]Data Sheet'!G82 -> 1299.52 | H4: ='[1]Data Sheet'!H82 -> 2526.21 | I4: ='[1]Data Sheet'!I82 -> 2572.98 | ... K4: ='[1]Data Sheet'!K82 -> 2611.6
A5: Cash from Investing Activity | B5: ='[1]Data Sheet'!B83 -> -149.85 | C5: ='[1]Data Sheet'!C83 -> -956.52 | D5: ='[1]Data Sheet'!D83 -> -852.22 | E5: ='[1]Data Sheet'!E83 -> -1525.93 | F5: ='[1]Data Sheet'!F83 -> 458.82 | G5: ='[1]Data Sheet'!G83 -> 914.19 | H5: ='[1]Data Sheet'!H83 -> -1507 | I5: ='[1]Data Sheet'!I83 -> 485.44 | ... K5: ='[1]Data Sheet'!K83 -> -741.38
A6: Cash from Financing Activity | B6: ='[1]Data Sheet'!B84 -> -295.08 | C6: ='[1]Data Sheet'!C84 -> -231.75 | D6: ='[1]Data Sheet'!D84 -> -352.68 | E6: ='[1]Data Sheet'!E84 -> 57.94 | F6: ='[1]Data Sheet'!F84 -> -2243.69 | G6: ='[1]Data Sheet'!G84 -> -2245.84 | H6: ='[1]Data Sheet'!H84 -> -1028.37 | I6: ='[1]Data Sheet'!I84 -> -2839.13 | ... K6: ='[1]Data Sheet'!K84 -> -1782.62
A7: Net Cash Flow | B7: ='[1]Data Sheet'!B85 -> -3.65 | C7: ='[1]Data Sheet'!C85 -> 60.5 | D7: ='[1]Data Sheet'!D85 -> -49.12 | E7: ='[1]Data Sheet'!E85 -> 16.54 | F7: ='[1]Data Sheet'!F85 -> 66.2 | G7: ='[1]Data Sheet'!G85 -> -32.13 | H7: ='[1]Data Sheet'!H85 -> -9.16 | I7: ='[1]Data Sheet'!I85 -> 219.29 | ... K7: ='[1]Data Sheet'!K85 -> 87.6

Sheet Raw FS
C1: BRITANNIA INDUSTRIES LIMITED
B3: ="Income Statement"&" "&"-"&" "&'Data Sheet'!B1 -> Income Statement - BRITANNIA INDUSTRIES LTD
B5: Particulars | C5: ='Cash Flow Data'!D2 -> 42795 | D5: =C5+365 -> 43160 | E5: =D5+365 -> 43525 | F5: =E5+366 -> 43891 | G5: =F5+366 -> 44257 | H5: =G5+366 -> 44623 | I5: =H5+366 -> 44989 | J5: =I5+366 -> 45355 | K5: =J5+366 -> 45721 | L5: =K5+366 -> 46087
B7: Equity Capital | C7: 24 | D7: 24 | E7: 24 | F7: 24 | G7: 24 | H7: 24 | I7: 24 | J7: 24 | K7: 24 | L7: 24
B8: Reserves | C8: 2672 | D8: 3382 | E8: 4229 | F8: 4379 | G8: 3524 | H8: 2534 | I8: 3510 | J8: 3917 | K8: 4332 | L8: 5082
B9: Borrowings -
B10: Long term Borrowings | C10: 31 | D10: 85 | E10: 62 | F10: 766 | G10: 748 | H10: 707 | I10: 1552 | J10: 905 | K10: 713 | L10: 286
B11: Short term Borrowings | C11: 84 | D11: 94 | E11: 76 | F11: 748 | G11: 1339 | H11: 1759 | I11: 1429 | J11: 1136 | K11: 512 | L11: 1072
B12: Lease Liabilities | C12: 0 | D12: 0 | E12: 0 | F12: 0 | G12: 0 | H12: 16 | I12: 17 | J12: 24 | K12: 22 | L12: 22
B13: Other Borrowings | C13: 9 | D13: 22 | E13: 18 | F13: 24 | G13: 20 | H13: 0 | I13: 0 | J13: 0 | K13: 0 | L13: 0
B14: Other Liabilities -
B15: Non controlling int | C15: 3 | D15: 13 | E15: 33 | F15: 36 | G15: 36 | H15: 28 | I15: 30 | J15: 24 | K15: 26 | L15: 29
B16: Trade Payables | C16: 757 | D16: 994 | E16: 1141 | F16: 1047 | G16: 1315 | H16: 1323 | I16: 1449 | J16: 1627 | K16: 1752 | L16: 1896
B17: Advance from Customers | C17: 17 | D17: 31 | E17: 41 | F17: 78 | G17: 55 | H17: 34 | I17: 55 | J17: 42 | K17: 46 | L17: 53
B18: Other liability items | C18: 511 | D18: 543 | E18: 615 | F18: 729 | G18: 940 | H18: 1103 | I18: 1285 | J18: 1371 | K18: 1410 | L18: 1265
B19: Total Liabilities | C19: =SUM(C7:C18) -> 4108 | D19: =SUM(D7:D18) -> 5188 | E19: =SUM(E7:E18) -> 6239 | F19: =SUM(F7:F18) -> 7831 | G19: =SUM(G7:G18) -> 8001 | H19: =SUM(H7:H18) -> 7528 | I19: =SUM(I7:I18) -> 9351 | J19: =SUM(J7:J18) -> 9070 | ... L19: =SUM(L7:L18) -> 9729
B21: Fixed Assets -
B22: Land | C22: 128 | D22: 246 | E22: 247 | F22: 319 | G22: 326 | H22: 334 | I22: 376 | J22: 384 | K22: 395 | L22: 397
B23: Building | C23: 376 | D23: 515 | E23: 660 | F23: 732 | G23: 758 | H23: 782 | I23: 1143 | J23: 1298 | K23: 1395 | L23: 1429
B24: Plant Machinery | C24: 641 | D24: 705 | E24: 1053 | F24: 1305 | G24: 1407 | H24: 1546 | I24: 2303 | J24: 2543 | K24: 2844 | L24: 3028
B25: Equipments | C25: 22 | D25: 25 | E25: 31 | F25: 40 | G25: 46 | H25: 52 | I25: 61 | J25: 75 | K25: 81 | L25: 79
B26: Furniture n fittings | C26: 25 | D26: 25 | E26: 28 | F26: 31 | G26: 32 | H26: 32 | I26: 43 | J26: 46 | K26: 49 | L26: 50
B27: Vehicles | C27: 2 | D27: 2 | E27: 3 | F27: 5 | G27: 5 | H27: 6 | I27: 10 | J27: 10 | K27: 9 | L27: 9
B28: Intangible Assets | C28: 128 | D28: 128 | E28: 134 | F28: 143 | G28: 139 | H28: 140 | I28: 130 | J28: 131 | K28: 134 | L28: 146
B29: Other fixed assets | C29: 36 | D29: 36 | E29: 40 | F29: 43 | G29: 46 | H29: 57 | I29: 86 | J29: 72 | K29: 67 | L29: 67
B30: Gross Block | C30: =SUM(C22:C29) -> 1358 | D30: =SUM(D22:D29) -> 1682 | E30: =SUM(E22:E29) -> 2196 | F30: =SUM(F22:F29) -> 2618 | G30: =SUM(G22:G29) -> 2759 | H30: =SUM(H22:H29) -> 2949 | I30: =SUM(I22:I29) -> 4152 | J30: =SUM(J22:J29) -> 4559 | ... L30: =SUM(L22:L29) -> 5205
B31: Accumulated Depreciation | C31: 199 | D31: 338 | E31: 507 | F31: 739 | G31: 967 | H31: 1195 | I31: 1495 | J31: 1788 | K31: 2070 | L31: 2356
B32: Net Block | C32: =C30-C31 -> 1159 | D32: =D30-D31 -> 1344 | E32: =E30-E31 -> 1689 | F32: =F30-F31 -> 1879 | G32: =G30-G31 -> 1792 | H32: =H30-H31 -> 1754 | I32: =I30-I31 -> 2657 | J32: =J30-J31 -> 2771 | ... L32: =L30-L31 -> 2849
B34: CWIP | C34: 30 | D34: 203 | E34: 101 | F34: 40 | G34: 117 | H34: 536 | I34: 105 | J34: 188 | K34: 89 | L34: 39
B35: Investments | C35: 487 | D35: 1079 | E35: 1476 | F35: 2893 | G35: 2781 | H35: 1762 | I35: 3324 | J35: 2767 | K35: 2865 | L35: 3610
B37: Other Assets -
B38: Inventories | C38: 661 | D38: 653 | E38: 781 | F38: 741 | G38: 1091 | H38: 1367 | I38: 1193 | J38: 1181 | K38: 1237 | L38: 1346
B39: Trade receivables - | C39: 179 | D39: 305 | E39: 394 | F39: 320 | G39: 257 | H39: 332 | I39: 329 | J39: 393 | K39: 449 | L39: 469
B40: Cash Equivalents | C40: 121 | D40: 186 | E40: 110 | F40: 123 | G40: 211 | H40: 185 | I40: 198 | J40: 446 | K40: 312 | L40: 352
B41: Loans n Advances | C41: 217 | D41: 150 | E41: 63 | F41: 50 | G41: 45 | H41: 63 | I41: 83 | J41: 62 | K41: 67 | L41: 55
B42: Other asset items | C42: 1254 | D42: 1267 | E42: 1623 | F42: 1784 | G42: 1705 | H42: 1528 | I42: 1463 | J42: 1263 | K42: 914 | L42: 1009
B43: Total Assets | C43: =SUM(C32:C42) -> 4108 | D43: =SUM(D32:D42) -> 5187 | E43: =SUM(E32:E42) -> 6237 | F43: =SUM(F32:F42) -> 7830 | G43: =SUM(G32:G42) -> 7999 | H43: =SUM(H32:H42) -> 7527 | I43: =SUM(I32:I42) -> 9352 | J43: =SUM(J32:J42) -> 9071 | ... L43: =SUM(L32:L42) -> 9729
B46: Particulars | C46: =C5 -> 42795 | D46: =C46+365 -> 43160 | E46: =D46+365 -> 43525 | F46: =E46+366 -> 43891 | G46: =F46+366 -> 44257 | H46: =G46+366 -> 44623 | I46: =H46+366 -> 44989 | J46: =I46+366 -> 45355 | K46: =J46+366 -> 45721 | L46: =K46+366 -> 46087
B48: Cash from Operating Activity - | C48: 441 | D48: 1249 | E48: 1156 | F48: 1485 | G48: 1851 | H48: 1300 | I48: 2526 | J48: 2573 | K48: 2491 | L48: 2612
B49: Profit from operations | C49: 1289 | D49: 1517 | E49: 1754 | F49: 1860 | G49: 2540 | H49: 2214 | I49: 2846 | J49: 3177 | K49: 3174 | L49: 3555
...

Sheet One Page Profile
B2: ='Data Sheet'!B1 -> BRITANNIA INDUSTRIES LTD
B3: (BRITANNIA) | BSE Code: 500825)
B4: INR 5,181.50 1st Sept 2026
B5: 52 Week (High - INR 6,336.95 & Low - 5,038)
L6: Prepared by Pushti Gandhi
B8: Britannia Industries Limited is an Indian multinational food products company, which sells biscuits, breads, and dairy products. Founded
B9: in 1892, it is one of India's oldest existing companies and currently part of the Wadia Group headed by Nusli Wadia. As of 2023, about 80%
B10: of its revenues came from biscuit products. It is one of India's leading food companies with a 100 year legacy and annual revenues in excess
B11: of Rs. 16,000 Cr. Britannia is among the most trusted food brands, and manufactures India's favorite brands like Good Day, Tiger, NutriChoice,
B12: Milk Bikis and Marigold.
B14: INR (Crs.)
B15: Key Financial Metrics | C15: ='Data Sheet'!G16 -> 44651 | D15: ='Data Sheet'!H16 -> 45016 | E15: ='Data Sheet'!I16 -> 45382 | F15: ='Data Sheet'!J16 -> 45747 | G15: ='Data Sheet'!K16 -> 46112 | I15: Share Price - 5year
B17: Total Sales | C17: ='Profit & Loss'!G4 -> 14136.26 | D17: ='Profit & Loss'!H4 -> 16300.55 | E17: ='Profit & Loss'!I4 -> 16769.27 | F17: ='Profit & Loss'!J4 -> 17942.67 | G17: ='Profit & Loss'!K4 -> 19151.59
B18: Sales Growth (y-o-y) | C18: ='Profit & Loss'!G28 -> 0.076134999 | D18: ='Profit & Loss'!H28 -> 0.15310202 | E18: ='Profit & Loss'!I28 -> 0.028754858 | F18: ='Profit & Loss'!J28 -> 0.069973231 | G18: ='Profit & Loss'!K28 -> 0.067376817
B19: Gross Profit Margin (%) | C19: ='Historical FS'!H19 -> 0.27332052 | D19: ='Historical FS'!I19 -> 0.29967823 | E19: ='Historical FS'!J19 -> 0.31994058 | F19: ='Historical FS'!K19 -> 0.29661249 | G19: ='Historical FS'!L19 -> 0.30970588
B20: EBITDA Margin (%) | C20: ='Historical FS'!H25 -> 0.15572082 | D20: ='Historical FS'!I25 -> 0.1736696 | E20: ='Historical FS'!J25 -> 0.18883648 | F20: ='Historical FS'!K25 -> 0.17703107 | G20: ='Historical FS'!L25 -> 0.18350121
B21: EBIT Margin (%) | C21: ='Historical FS'!H34 -> 0.14153461 | D21: ='Historical FS'!I34 -> 0.15981056 | E21: ='Historical FS'!J34 -> 0.17091919 | F21: ='Historical FS'!K34 -> 0.15956767 | G21: ='Historical FS'!L34 -> 0.16591364
B22: Net Profit Margin (%) | C22: ='Historical FS'!H43 -> 0.091546845 | D22: ='Historical FS'!I43 -> 0.10548417 | E22: ='Historical FS'!J43 -> 0.11467047 | F22: ='Historical FS'!K43 -> 0.11010401 | G22: ='Historical FS'!L43 -> 0.12077222
B23: Earnings Per Share (in Rs.) | C23: ='Historical FS'!H47 -> 53.720631 | D23: ='Historical FS'!I47 -> 71.37609 | E23: ='Historical FS'!J47 -> 79.823163 | F23: ='Historical FS'!K47 -> 82.007472 | G23: ='Historical FS'!L47 -> 96.014114
B24: EPS Growth (y-o-y) | C24: ='Historical FS'!H48 -> -0.15830038 | D24: ='Historical FS'!I48 -> 0.32865323 | E24: ='Historical FS'!J48 -> 0.11834598 | F24: ='Historical FS'!K48 -> 0.027364348 | G24: ='Historical FS'!L48 -> 0.17079714
B25: Dividend Per Share (in Rs) | C25: ='Historical FS'!H50 -> 56.499792 | D25: ='Historical FS'!I50 -> 72 | E25: ='Historical FS'!J50 -> 73.500208 | F25: ='Historical FS'!K50 -> 75 | G25: ='Historical FS'!L50 -> 90.499792
B26: DPS Growth (y-o-y) | C26: ='Historical FS'!H50/'Historical FS'!G50-1 -> -0.64127163 | D26: ='Historical FS'!I50/'Historical FS'!H50-1 -> 0.27434096 | E26: ='Historical FS'!J50/'Historical FS'!I50-1 -> 0.020836216 | F26: ='Historical FS'!K50/'Historical FS'!J50-1 -> 0.020405282 | G26: ='Historical FS'!L50/'Historical FS'!K50-1 -> 0.2066639
B28: Key Financial Ratios | C28: =C15 -> 44651 | D28: =D15 -> 45016 | E28: =E15 -> 45382 | F28: =F15 -> 45747 | G28: =G15 -> 46112 | I28: Volume - 5year
B30: Price to Earnings | C30: ='Profit & Loss'!G14 -> 50.656586 | D30: ='Profit & Loss'!H14 -> 44.845352 | E30: ='Profit & Loss'!I14 -> 55.290896 | F30: ='Profit & Loss'!J14 -> 54.58681 | G30: ='Profit & Loss'!K14 -> 51.56526
B31: EV/EBITDA | C31: ='Profit & Loss'!G35 -> 36.132338 | D31: ='Profit & Loss'!H35 -> 37.768768 | E31: ='Profit & Loss'!I35 -> 37.873027 | F31: ='Profit & Loss'!J35 -> 37.735667 | G31: ='Profit & Loss'!K35 -> 37.4659
B32: EV/Sales | C32: ='Profit & Loss'!G36 -> 5.6265572 | D32: ='Profit & Loss'!H36 -> 6.5592869 | E32: ='Profit & Loss'!I36 -> 7.1518094 | F32: ='Profit & Loss'!J36 -> 6.6803854 | G32: ='Profit & Loss'!K36 -> 6.8750381
B33: Price to Book Value | C33: ='Profit & Loss'!G39 -> 30.195135 | D33: ='Profit & Loss'!H39 -> 29.460283 | E33: ='Profit & Loss'!I39 -> 30.016849 | F33: ='Profit & Loss'!J39 -> 27.304308 | G33: ='Profit & Loss'!K39 -> 25.582794
B34: Return on Equity (%) | C34: ='Ratio Analysis'!H29 -> 0.505895 | D34: ='Ratio Analysis'!I29 -> 0.48650782 | E34: ='Ratio Analysis'!J29 -> 0.48786762 | F34: ='Ratio Analysis'!K29 -> 0.45355532 | G34: ='Ratio Analysis'!L29 -> 0.45294288
B35: Return on Capital Employed (%) | C35: ='Ratio Analysis'!H27 -> 0.39703332 | D35: ='Ratio Analysis'!I27 -> 0.39882786 | E35: ='Ratio Analysis'!J27 -> 0.47718298 | F35: ='Ratio Analysis'!K27 -> 0.51105899 | G35: ='Ratio Analysis'!L27 -> 0.48983943
B37: Top Shareholders of BRITANNIA | C37: N. of Shares Held (In Crs.) | E37: (%) Holding | F37: Market Value (In Crs.) | I37: Shareholding Pattern
B38: ASSOCIATED BISCUITS INTERNATIONAL LIMITED | D38: 10.7809 | E38: 0.4476 | G38: 51865.832
B39: ICICI PRUDENTIAL INDIA OPPORTUNITIES FUND | D39: 1.0450013 | E39: 0.0434 | G39: 5027.3968
B40: LIFE INSURANCE CORPORATION OF INDIA | D40: 0.6534873 | E40: 0.0271 | G40: 3143.8621
B41: HDFC MUTUAL FUND - HDFC MNC FUND | D41: 0.4236895 | E41: 0.0176 | G41: 2038.3278
B42: LICI ASM NON PAR | D42: 0.3060463 | E42: 0.0127 | G42: 1472.3581
B44: Managerial Remuneration | C44: Designation | D44: Remuneration (In Crs.) | F44: X of Median Salary | I44: Capital Structure
B46: Mr. Nusli N. Wadia | C46: Chairman | D46: 5.32 | F46: 85.94X | I46: Share Price on XXX | N46: ='Data Sheet'!B8 -> 5250
B47: Mr. Rakshit Hargave | C47: CEO & MD | D47: 8.5 | F47: 50.2X | I47: No. of Share O/s | N47: ='Data Sheet'!B6 -> 24.077305
B48: Mr. N. Venkataraman | C48: ED & CFO | D48: 4.4 | F48: 69.20X | I48: Market Capitalization | N48: =N46*N47 -> 126405.85
I49: Less: Cash & Equivalents | N49: ='Data Sheet'!K69*-1 -> -352.44
...

Sheet Britannia 5 Yrs data
A1: Britannia Industries
J3: 10000000
A4: Date | B4: Adj Close | C4: Volume
A5: 44469 | B5: 3657.86 | C5: 0.217501 | E5: 1000000
A6: 44470 | B6: 3632.06 | C6: 0.181917 | H6: Shareholder's name | I6: Total Shares Held | J6: Shareholding (%) | K6: Quarter Ending | L6: Share Price
A7: 44473 | B7: 3605.94 | C7: 0.372752 | H7: ASSOCIATED BISCUITS INTERNATIONAL LIMITED | I7: 10.7809 | J7: 44.76 | K7: 46174 | L7: =4810.9*I7 -> 51865.832
A8: 44474 | B8: 3596.03 | C8: 0.131731 | H8: ICICI PRUDENTIAL INDIA OPPORTUNITIES FUND | I8: 1.0450013 | J8: 4.34 | K8: 46174 | L8: =4810.9*I8 -> 5027.3968
A9: 44475 | B9: 3648.27 | C9: 0.40984 | H9: LIFE INSURANCE CORPORATION OF INDIA | I9: 0.6534873 | J9: 2.71 | K9: 46174 | L9: =4810.9*I9 -> 3143.8621
A10: 44476 | B10: 3613.07 | C10: 0.187556 | H10: HDFC MUTUAL FUND - HDFC MNC FUND | I10: 0.4236895 | J10: 1.76 | K10: 46174 | L10: =4810.9*I10 -> 2038.3278
A11: 44477 | B11: 3597.05 | C11: 0.31687 | H11: LICI ASM NON PAR | I11: 0.3060463 | J11: 1.27 | K11: 46174 | L11: =4810.9*I11 -> 1472.3581
A12: 44480 | B12: 3557.5 | C12: 0.253051 | H12: VALLETORT ENTERPRISES PTE LTD | I12: 0.278502 | J12: 1.16 | K12: 46174 | L12: =4810.9*I12 -> 1339.8453
A13: 44481 | B13: 3582.83 | C13: 0.253262 | H13: NACUPA ENTERPRISES PTE LTD | I13: 0.278502 | J13: 1.16 | K13: 46174 | L13: =4810.9*I13 -> 1339.8453
A14: 44482 | B14: 3597.42 | C14: 0.174222 | H14: DOWBIGGIN ENTERPRISES PTE LTD | I14: 0.278502 | J14: 1.16 | K14: 46174 | L14: =4810.9*I14 -> 1339.8453
A15: 44483 | B15: 3607.75 | C15: 0.299078 | H15: BANNATYNE ENTERPRISES PTE LTD | I15: 0.278311 | J15: 1.16 | K15: 46174 | L15: =4810.9*I15 -> 1338.9264
A16: 44487 | B16: 3554.49 | C16: 0.256837 | H16: SPARGO ENTERPRISES PTE LTD | I16: 0.278502 | J16: 1.16 | K16: 46174 | L16: =4810.9*I16 -> 1339.8453
A17: 44488 | B17: 3516.09 | C17: 0.282932
A18: 44489 | B18: 3484.69 | C18: 0.523002
A19: 44490 | B19: 3440.55 | C19: 0.335589
A20: 44491 | B20: 3418 | C20: 0.192033 | H20: FII | I20: 0.134
A21: 44494 | B21: 3363.39 | C21: 0.289025 | H21: DII | I21: 0.2088
A22: 44495 | B22: 3420.59 | C22: 0.326825 | H22: Public & Government | I22: 0.1517
A23: 44496 | B23: 3425.27 | C23: 0.441016 | H23: Promoter | I23: 0.5055
A24: 44497 | B24: 3410.5 | C24: 0.193658
A25: 44498 | B25: 3404.8 | C25: 0.283538
A26: 44501 | B26: 3407.02 | C26: 0.139766
A27: 44502 | B27: 3411.42 | C27: 0.151547
A28: 44503 | B28: 3362.28 | C28: 0.185296
A29: 44504 | B29: 3362.28 | C29: -
A30: 44508 | B30: 3443.66 | C30: 0.336938
A31: 44509 | B31: 3354.64 | C31: 1.399094
A32: 44510 | B32: 3425.87 | C32: 0.706755
A33: 44511 | B33: 3374.83 | C33: 0.298625
A34: 44512 | B34: 3416.1 | C34: 0.27506
A35: 44515 | B35: 3466.72 | C35: 0.320669
A36: 44516 | B36: 3418.69 | C36: 0.199179
A37: 44517 | B37: 3348.57 | C37: 0.250996
A38: 44518 | B38: 3308.33 | C38: 0.248828
A39: 44522 | B39: 3317.59 | C39: 0.364653
A40: 44523 | B40: 3392.2 | C40: 0.365672
A41: 44524 | B41: 3356.26 | C41: 0.149025
...

Sheet Historical FS
B2: ='Data Sheet'!B1 -> BRITANNIA INDUSTRIES LTD
B3: (BRITANNIA) | BSE Code: 500825)
B4: INR 5,181.50 1st Sept 2026
B5: 52 Week (High - INR 6,336.95 & Low - 5,038)
K7: Prepared by Pushti Gandhi
B8: ="Historical Financial Statement"&" "&"-"&" "&'Data Sheet'!B1 -> Historical Financial Statement - BRITANNIA INDUSTRIES LTD
B9: Years | C9: ='Data Sheet'!B16 -> 42825 | D9: =C9+365 -> 43190 | E9: =D9+365 -> 43555 | F9: =E9+365 -> 43920 | G9: =F9+365 -> 44285 | H9: =G9+365 -> 44650 | I9: =H9+365 -> 45015 | J9: =I9+365 -> 45380 | K9: =J9+365 -> 45745 | L9: =K9+365 -> 46110 | M9: LTM
A11: # | B11: Income Statement
B12: Sales | C12: =IFERROR('Data Sheet'!B17,0) -> 9054.09 | D12: =IFERROR('Data Sheet'!C17,0) -> 9913.99 | E12: =IFERROR('Data Sheet'!D17,0) -> 11054.67 | F12: =IFERROR('Data Sheet'!E17,0) -> 11599.55 | G12: =IFERROR('Data Sheet'!F17,0) -> 13136.14 | H12: =IFERROR('Data Sheet'!G17,0) -> 14136.26 | I12: =IFERROR('Data Sheet'!H17,0) -> 16300.55 | J12: =IFERROR('Data Sheet'!I17,0) -> 16769.27 | ... L12: =IFERROR('Data Sheet'!K17,0) -> 19151.59 | M12: =IFERROR(SUM('Data Sheet'!G42:J42),0) -> 19151.59
B13: Sales Growth | C13: - | D13: =(D12/C12-1) -> 0.094973653 | E13: =(E12/D12-1) -> 0.11505761 | F13: =(F12/E12-1) -> 0.049289576 | G13: =(G12/F12-1) -> 0.13246979 | H13: =(H12/G12-1) -> 0.076134999 | I13: =(I12/H12-1) -> 0.15310202 | J13: =(J12/I12-1) -> 0.028754858 | K13: =(K12/J12-1) -> 0.069973231 | ... M13: =(M12/L12-1) -> 0
B15: COGS | C15: =IFERROR(SUM('Data Sheet'!B18,'Data Sheet'!B20:B22)-1*'Data Sheet'!B19,0) -> 6555.5 | D15: =IFERROR(SUM('Data Sheet'!C18,'Data Sheet'!C20:C22)-1*'Data Sheet'!C19,0) -> 7125.12 | E15: =IFERROR(SUM('Data Sheet'!D18,'Data Sheet'!D20:D22)-1*'Data Sheet'!D19,0) -> 7799.77 | F15: =IFERROR(SUM('Data Sheet'!E18,'Data Sheet'!E20:E22)-1*'Data Sheet'!E19,0) -> 8202.54 | G15: =IFERROR(SUM('Data Sheet'!F18,'Data Sheet'!F20:F22)-1*'Data Sheet'!F19,0) -> 9007.98 | H15: =IFERROR(SUM('Data Sheet'!G18,'Data Sheet'!G20:G22)-1*'Data Sheet'!G19,0) -> 10272.53 | I15: =IFERROR(SUM('Data Sheet'!H18,'Data Sheet'!H20:H22)-1*'Data Sheet'!H19,0) -> 11415.63 | J15: =IFERROR(SUM('Data Sheet'!I18,'Data Sheet'!I20:I22)-1*'Data Sheet'!I19,0) -> 11404.1 | ... L15: =IFERROR(SUM('Data Sheet'!K18,'Data Sheet'!K20:K22)-1*'Data Sheet'!K19,0) -> 13220.23 | M15: =IFERROR(SUM('Data Sheet'!G43:J43),0) -> 15637.25
B16: Gross Margins (COGS% of Sales) | C16: =(C15/C12) -> 0.72403742 | D16: =(D15/D12) -> 0.71869348 | E16: =(E15/E12) -> 0.70556335 | F16: =(F15/F12) -> 0.70714295 | G16: =(G15/G12) -> 0.68574026 | H16: =(H15/H12) -> 0.72667948 | I16: =(I15/I12) -> 0.70032177 | J16: =(J15/J12) -> 0.68005942 | ... M16: =(M15/M12) -> 0.81649879
B18: Gross Profit | C18: =IFERROR(C12-C15,0) -> 2498.59 | D18: =IFERROR(D12-D15,0) -> 2788.87 | E18: =IFERROR(E12-E15,0) -> 3254.9 | F18: =IFERROR(F12-F15,0) -> 3397.01 | G18: =IFERROR(G12-G15,0) -> 4128.16 | H18: =IFERROR(H12-H15,0) -> 3863.73 | I18: =IFERROR(I12-I15,0) -> 4884.92 | J18: =IFERROR(J12-J15,0) -> 5365.17 | ... M18: =IFERROR(M12-M15,0) -> 3514.34
B19: Gross Margins (GP % of Sales) | C19: =IFERROR(C18/C12,0) -> 0.27596258 | D19: =IFERROR(D18/D12,0) -> 0.28130652 | E19: =IFERROR(E18/E12,0) -> 0.29443665 | F19: =IFERROR(F18/F12,0) -> 0.29285705 | G19: =IFERROR(G18/G12,0) -> 0.31425974 | H19: =IFERROR(H18/H12,0) -> 0.27332052 | I19: =IFERROR(I18/I12,0) -> 0.29967823 | J19: =IFERROR(J18/J12,0) -> 0.31994058 | ... M19: =IFERROR(M18/M12,0) -> 0.18350121
B21: Selling & General Expense | C21: =IFERROR(SUM('Data Sheet'!B23:B24),0) -> 1220.41 | D21: =IFERROR(SUM('Data Sheet'!C23:C24),0) -> 1287.4 | E21: =IFERROR(SUM('Data Sheet'!D23:D24),0) -> 1522.45 | F21: =IFERROR(SUM('Data Sheet'!E23:E24),0) -> 1553.83 | G21: =IFERROR(SUM('Data Sheet'!F23:F24),0) -> 1618.87 | H21: =IFERROR(SUM('Data Sheet'!G23:G24),0) -> 1662.42 | I21: =IFERROR(SUM('Data Sheet'!H23:H24),0) -> 2054.01 | J21: =IFERROR(SUM('Data Sheet'!I23:I24),0) -> 2198.52 | ... L21: =IFERROR(SUM('Data Sheet'!K23:K24),0) -> 2417.02
B22: S&G % of Sales | C22: =IFERROR(C21/C12,0) -> 0.13479102 | D22: =IFERROR(D21/D12,0) -> 0.1298569 | E22: =IFERROR(E21/E12,0) -> 0.13772008 | F22: =IFERROR(F21/F12,0) -> 0.13395606 | G22: =IFERROR(G21/G12,0) -> 0.12323788 | H22: =IFERROR(H21/H12,0) -> 0.1175997 | I22: =IFERROR(I21/I12,0) -> 0.12600863 | J22: =IFERROR(J21/J12,0) -> 0.1311041 | ... M22: =IFERROR(M21/M12,0) -> 0
B24: EBITDA | C24: =IFERROR(C18-C21,0) -> 1278.18 | D24: =IFERROR(D18-D21,0) -> 1501.47 | E24: =IFERROR(E18-E21,0) -> 1732.45 | F24: =IFERROR(F18-F21,0) -> 1843.18 | G24: =IFERROR(G18-G21,0) -> 2509.29 | H24: =IFERROR(H18-H21,0) -> 2201.31 | I24: =IFERROR(I18-I21,0) -> 2830.91 | J24: =IFERROR(J18-J21,0) -> 3166.65 | ... M24: =IFERROR(M18-M21,0) -> 3514.34
B25: EBITDA Margin | C25: =IFERROR(C24/C12,0) -> 0.14117156 | D25: =IFERROR(D24/D12,0) -> 0.15144962 | E25: =IFERROR(E24/E12,0) -> 0.15671657 | F25: =IFERROR(F24/F12,0) -> 0.15890099 | G25: =IFERROR(G24/G12,0) -> 0.19102187 | H25: =IFERROR(H24/H12,0) -> 0.15572082 | I25: =IFERROR(I24/I12,0) -> 0.1736696 | J25: =IFERROR(J24/J12,0) -> 0.18883648 | ... M25: =IFERROR(M24/M12,0) -> 0.18350121
B27: Interest | C27: =IFERROR('Data Sheet'!B27,0) -> 5.45 | D27: =IFERROR('Data Sheet'!C27,0) -> 7.59 | E27: =IFERROR('Data Sheet'!D27,0) -> 9.09 | F27: =IFERROR('Data Sheet'!E27,0) -> 76.9 | G27: =IFERROR('Data Sheet'!F27,0) -> 110.9 | H27: =IFERROR('Data Sheet'!G27,0) -> 144.29 | I27: =IFERROR('Data Sheet'!H27,0) -> 169.1 | J27: =IFERROR('Data Sheet'!I27,0) -> 164 | ... L27: =IFERROR('Data Sheet'!K27,0) -> 112.76 | M27: =IFERROR(SUM('Data Sheet'!H46:K46),0) -> 109.48
B28: Interest % of Sales | C28: =IFERROR(C27/C12,0) -> 0.00060193791 | D28: =IFERROR(D27/D12,0) -> 0.00076558479 | E28: =IFERROR(E27/E12,0) -> 0.00082227692 | F28: =IFERROR(F27/F12,0) -> 0.0066295675 | G28: =IFERROR(G27/G12,0) -> 0.0084423583 | H28: =IFERROR(H27/H12,0) -> 0.010207084 | I28: =IFERROR(I27/I12,0) -> 0.010373883 | J28: =IFERROR(J27/J12,0) -> 0.0097797936 | ... M28: =IFERROR(M27/M12,0) -> 0.0057164966
B30: Depreciation | C30: =IFERROR('Data Sheet'!B26,0) -> 119.27 | D30: =IFERROR('Data Sheet'!C26,0) -> 142.07 | E30: =IFERROR('Data Sheet'!D26,0) -> 161.88 | F30: =IFERROR('Data Sheet'!E26,0) -> 184.81 | G30: =IFERROR('Data Sheet'!F26,0) -> 197.85 | H30: =IFERROR('Data Sheet'!G26,0) -> 200.54 | I30: =IFERROR('Data Sheet'!H26,0) -> 225.91 | J30: =IFERROR('Data Sheet'!I26,0) -> 300.46 | ... L30: =IFERROR('Data Sheet'!K26,0) -> 336.83 | M30: =IFERROR(SUM('Data Sheet'!H45:K45),0) -> 334.3
B31: Depreciation % of Sales | C31: =IFERROR(C30/C12,0) -> 0.013173052 | D31: =IFERROR(D30/D12,0) -> 0.014330255 | E31: =IFERROR(E30/E12,0) -> 0.014643585 | F31: =IFERROR(F30/F12,0) -> 0.015932515 | G31: =IFERROR(G30/G12,0) -> 0.015061502 | H31: =IFERROR(H30/H12,0) -> 0.014186213 | I31: =IFERROR(I30/I12,0) -> 0.013859042 | J31: =IFERROR(J30/J12,0) -> 0.017917298 | ... M31: =IFERROR(M30/M12,0) -> 0.01745547
B33: EBIT | C33: =IFERROR(C24-C30,0) -> 1158.91 | D33: =IFERROR(D24-D30,0) -> 1359.4 | E33: =IFERROR(E24-E30,0) -> 1570.57 | F33: =IFERROR(F24-F30,0) -> 1658.37 | G33: =IFERROR(G24-G30,0) -> 2311.44 | H33: =IFERROR(H24-H30,0) -> 2000.77 | I33: =IFERROR(I24-I30,0) -> 2605 | J33: =IFERROR(J24-J30,0) -> 2866.19 | ... M33: =IFERROR(M24-M30,0) -> 3180.04
B34: EBIT Margin | C34: =IFERROR(C33/C12,0) -> 0.12799851 | D34: =IFERROR(D33/D12,0) -> 0.13711936 | E34: =IFERROR(E33/E12,0) -> 0.14207299 | F34: =IFERROR(F33/F12,0) -> 0.14296848 | G34: =IFERROR(G33/G12,0) -> 0.17596037 | H34: =IFERROR(H33/H12,0) -> 0.14153461 | I34: =IFERROR(I33/I12,0) -> 0.15981056 | J34: =IFERROR(J33/J12,0) -> 0.17091919 | ... M34: =IFERROR(M33/M12,0) -> 0.16604574
B36: Earnings Before Tax (EBT) | C36: =IFERROR(C24-SUM(C27,C30),0) -> 1153.46 | D36: =IFERROR(D24-SUM(D27,D30),0) -> 1351.81 | E36: =IFERROR(E24-SUM(E27,E30),0) -> 1561.48 | F36: =IFERROR(F24-SUM(F27,F30),0) -> 1581.47 | G36: =IFERROR(G24-SUM(G27,G30),0) -> 2200.54 | H36: =IFERROR(H24-SUM(H27,H30),0) -> 1856.48 | I36: =IFERROR(I24-SUM(I27,I30),0) -> 2435.9 | J36: =IFERROR(J24-SUM(J27,J30),0) -> 2702.19 | ... M36: =IFERROR(M24-SUM(M27,M30),0) -> 3070.56
B37: EBT % of Sales (EBT Margin) | C37: =IFERROR(C36/C12,0) -> 0.12739657 | D37: =IFERROR(D36/D12,0) -> 0.13635378 | E37: =IFERROR(E36/E12,0) -> 0.14125071 | F37: =IFERROR(F36/F12,0) -> 0.13633891 | G37: =IFERROR(G36/G12,0) -> 0.16751801 | H37: =IFERROR(H36/H12,0) -> 0.13132752 | I37: =IFERROR(I36/I12,0) -> 0.14943668 | J37: =IFERROR(J36/J12,0) -> 0.16113939 | ... M37: =IFERROR(M36/M12,0) -> 0.16032925
B39: Tax | C39: =IFERROR('Data Sheet'!B29,0) -> 419.67 | D39: =IFERROR('Data Sheet'!C29,0) -> 514.22 | E39: =IFERROR('Data Sheet'!D29,0) -> 612.47 | F39: =IFERROR('Data Sheet'!E29,0) -> 450.7 | G39: =IFERROR('Data Sheet'!F29,0) -> 663.02 | H39: =IFERROR('Data Sheet'!G29,0) -> 562.35 | I39: =IFERROR('Data Sheet'!H29,0) -> 716.45 | J39: =IFERROR('Data Sheet'!I29,0) -> 779.25 | ... L39: =IFERROR('Data Sheet'!K29,0) -> 751.77 | M39: =IFERROR(SUM('Data Sheet'!H48:K48),0) -> 774.85
B40: Effective Tax Rate (Tax/EBT) | C40: =IFERROR(C39/C36,0) -> 0.36383576 | D40: =IFERROR(D39/D36,0) -> 0.38039369 | E40: =IFERROR(E39/E36,0) -> 0.39223685 | F40: =IFERROR(F39/F36,0) -> 0.28498802 | G40: =IFERROR(G39/G36,0) -> 0.30129877 | H40: =IFERROR(H39/H36,0) -> 0.30291196 | I40: =IFERROR(I39/I36,0) -> 0.29412127 | J40: =IFERROR(J39/J36,0) -> 0.28837721 | ... M40: =IFERROR(M39/M36,0) -> 0.25234811
B42: Net Profit (EBT - Tax) | C42: =IFERROR(C36-C39,0) -> 733.79 | D42: =IFERROR(D36-D39,0) -> 837.59 | E42: =IFERROR(E36-E39,0) -> 949.01 | F42: =IFERROR(F36-F39,0) -> 1130.77 | G42: =IFERROR(G36-G39,0) -> 1537.52 | H42: =IFERROR(H36-H39,0) -> 1294.13 | I42: =IFERROR(I36-I39,0) -> 1719.45 | J42: =IFERROR(J36-J39,0) -> 1922.94 | ... M42: =IFERROR(M36-M39,0) -> 2295.71
B43: Net Profit Margin (NP / Sales) | C43: =IFERROR(C42/C12,0) -> 0.081045141 | D43: =IFERROR(D42/D12,0) -> 0.084485661 | E43: =IFERROR(E42/E12,0) -> 0.085846977 | F43: =IFERROR(F42/F12,0) -> 0.097483954 | G43: =IFERROR(G42/G12,0) -> 0.11704504 | H43: =IFERROR(H42/H12,0) -> 0.091546845 | I43: =IFERROR(I42/I12,0) -> 0.10548417 | J43: =IFERROR(J42/J12,0) -> 0.11467047 | ... M43: =IFERROR(M42/M12,0) -> 0.11987047
B45: No. Of Equity Shares | C45: =IFERROR('Data Sheet'!B93,0) -> 24 | D45: =IFERROR('Data Sheet'!C93,0) -> 24.01 | E45: =IFERROR('Data Sheet'!D93,0) -> 24.03 | F45: =IFERROR('Data Sheet'!E93,0) -> 24.05 | G45: =IFERROR('Data Sheet'!F93,0) -> 24.09 | H45: =IFERROR('Data Sheet'!G93,0) -> 24.09 | I45: =IFERROR('Data Sheet'!H93,0) -> 24.09 | J45: =IFERROR('Data Sheet'!I93,0) -> 24.09 | ... L45: =IFERROR('Data Sheet'!K93,0) -> 24.09
B47: Earning Per Share | C47: =IFERROR(C42/C45,0) -> 30.574583 | D47: =IFERROR(D42/D45,0) -> 34.885048 | E47: =IFERROR(E42/E45,0) -> 39.492717 | F47: =IFERROR(F42/F45,0) -> 47.017464 | G47: =IFERROR(G42/G45,0) -> 63.823993 | H47: =IFERROR(H42/H45,0) -> 53.720631 | I47: =IFERROR(I42/I45,0) -> 71.37609 | J47: =IFERROR(J42/J45,0) -> 79.823163 | ... M47: =IFERROR(M42/M45,0) -> 0
B48: EPS Growth % | C48: - | D48: =(D47/C47-1) -> 0.14098196 | E48: =(E47/D47-1) -> 0.1320815 | F48: =(F47/E47-1) -> 0.19053503 | G48: =(G47/F47-1) -> 0.35745292 | H48: =(H47/G47-1) -> -0.15830038 | I48: =(I47/H47-1) -> 0.32865323 | J48: =(J47/I47-1) -> 0.11834598 | K48: =(K47/J47-1) -> 0.027364348 | ... M48: =(M47/L47-1) -> -1
B50: DPS (Dividend Per Share) | C50: =IFERROR('Data Sheet'!B31/'Data Sheet'!B93,0) -> 11 | D50: =IFERROR('Data Sheet'!C31/'Data Sheet'!C93,0) -> 12.499792 | E50: =IFERROR('Data Sheet'!D31/'Data Sheet'!D93,0) -> 15 | F50: =IFERROR('Data Sheet'!E31/'Data Sheet'!E93,0) -> 35 | G50: =IFERROR('Data Sheet'!F31/'Data Sheet'!F93,0) -> 157.50021 | H50: =IFERROR('Data Sheet'!G31/'Data Sheet'!G93,0) -> 56.499792 | I50: =IFERROR('Data Sheet'!H31/'Data Sheet'!H93,0) -> 72 | J50: =IFERROR('Data Sheet'!I31/'Data Sheet'!I93,0) -> 73.500208 | ... M50: =IFERROR('Data Sheet'!L31/'Data Sheet'!L93,0) -> 0
B51: Dividend Payout Ratio (DPS/EPS) | C51: =IFERROR(C50/C47,0) -> 0.35977596 | D51: =IFERROR(D50/D47,0) -> 0.35831373 | E51: =IFERROR(E50/E47,0) -> 0.37981686 | F51: =IFERROR(F50/F47,0) -> 0.74440426 | G51: =IFERROR(G50/G47,0) -> 2.4677272 | H51: =IFERROR(H50/H47,0) -> 1.0517336 | I51: =IFERROR(I50/I47,0) -> 1.0087412 | J51: =IFERROR(J50/J47,0) -> 0.92078796 | ... M51: =IFERROR(M50/M47,0) -> 0
B53: Retained Earnings | C53: =IF(C47>C50,1-C51,0) -> 0.64022404 | D53: =IF(D47>D50,1-D51,0) -> 0.64168627 | E53: =IF(E47>E50,1-E51,0) -> 0.62018314 | F53: =IF(F47>F50,1-F51,0) -> 0.25559574 | G53: =IF(G47>G50,1-G51,0) -> 0 | H53: =IF(H47>H50,1-H51,0) -> 0 | I53: =IF(I47>I50,1-I51,0) -> 0 | J53: =IF(J47>J50,1-J51,0) -> 0.07921204 | ... M53: =IF(M47>M50,1-M51,0) -> 0
A56: # | B56: Balance Sheet
B57: Equity Share Capital | C57: =IFERROR('Data Sheet'!B57,0) -> 24 | D57: =IFERROR('Data Sheet'!C57,0) -> 24.01 | E57: =IFERROR('Data Sheet'!D57,0) -> 24.03 | F57: =IFERROR('Data Sheet'!E57,0) -> 24.05 | G57: =IFERROR('Data Sheet'!F57,0) -> 24.09 | H57: =IFERROR('Data Sheet'!G57,0) -> 24.09 | I57: =IFERROR('Data Sheet'!H57,0) -> 24.09 | J57: =IFERROR('Data Sheet'!I57,0) -> 24.09 | ... L57: =IFERROR('Data Sheet'!K57,0) -> 24.09
B58: Reserves | C58: =IFERROR('Data Sheet'!B58,0) -> 2672.42 | D58: =IFERROR('Data Sheet'!C58,0) -> 3382.22 | E58: =IFERROR('Data Sheet'!D58,0) -> 4229.22 | F58: =IFERROR('Data Sheet'!E58,0) -> 4378.78 | G58: =IFERROR('Data Sheet'!F58,0) -> 3523.57 | H58: =IFERROR('Data Sheet'!G58,0) -> 2534.01 | I58: =IFERROR('Data Sheet'!H58,0) -> 3510.18 | J58: =IFERROR('Data Sheet'!I58,0) -> 3917.43 | ... L58: =IFERROR('Data Sheet'!K58,0) -> 5082.47
B59: Borrowings | C59: =IFERROR('Data Sheet'!B59,0) -> 124.56 | D59: =IFERROR('Data Sheet'!C59,0) -> 200.7 | E59: =IFERROR('Data Sheet'!D59,0) -> 156.02 | F59: =IFERROR('Data Sheet'!E59,0) -> 1537.59 | G59: =IFERROR('Data Sheet'!F59,0) -> 2106.94 | H59: =IFERROR('Data Sheet'!G59,0) -> 2481.2 | I59: =IFERROR('Data Sheet'!H59,0) -> 2997.37 | J59: =IFERROR('Data Sheet'!I59,0) -> 2064.96 | ... L59: =IFERROR('Data Sheet'!K59,0) -> 1380.28
...

Sheet Ratio Analysis
B2: ='Data Sheet'!B1 -> BRITANNIA INDUSTRIES LTD
B3: (BRITANNIA) | BSE Code: 500825)
B4: INR 5,181.50 1st Sept 2026
B5: 52 Week (High - INR 6,336.95 & Low - 5,038)
M7: Prepared by Pushti Gandhi
B8: ="Ratio Analysis of"&" "&"-"&" "&'Data Sheet'!B1 -> Ratio Analysis of - BRITANNIA INDUSTRIES LTD
B9: Years | C9: ='Data Sheet'!B16 -> 42825 | D9: =C9+365 -> 43190 | E9: =D9+365 -> 43555 | F9: =E9+365 -> 43920 | G9: =F9+365 -> 44285 | H9: =G9+365 -> 44650 | I9: =H9+365 -> 45015 | J9: =I9+365 -> 45380 | K9: =J9+365 -> 45745 | L9: =K9+365 -> 46110 | M9: Trend | N9: Mean | O9: Median
B11: Sales Growth | C11: 0 | D11: =IFERROR('Historical FS'!D13,0) -> 0.094973653 | E11: =IFERROR('Historical FS'!E13,0) -> 0.11505761 | F11: =IFERROR('Historical FS'!F13,0) -> 0.049289576 | G11: =IFERROR('Historical FS'!G13,0) -> 0.13246979 | H11: =IFERROR('Historical FS'!H13,0) -> 0.076134999 | I11: =IFERROR('Historical FS'!I13,0) -> 0.15310202 | J11: =IFERROR('Historical FS'!J13,0) -> 0.028754858 | K11: =IFERROR('Historical FS'!K13,0) -> 0.069973231 | L11: =IFERROR('Historical FS'!L13,0) -> 0.067376817 | N11: =IFERROR(AVERAGE(D11:L11),0) -> 0.087459173 | O11: =IFERROR(MEDIAN(C11:L11),0) -> 0.073054115
B12: EBITDA Growth | C12: 0 | D12: =IFERROR('Historical FS'!D24/'Historical FS'!C24-1,0) -> 0.17469371 | E12: =IFERROR('Historical FS'!E24/'Historical FS'!D24-1,0) -> 0.15383591 | F12: =IFERROR('Historical FS'!F24/'Historical FS'!E24-1,0) -> 0.063915265 | G12: =IFERROR('Historical FS'!G24/'Historical FS'!F24-1,0) -> 0.36139173 | H12: =IFERROR('Historical FS'!H24/'Historical FS'!G24-1,0) -> -0.12273591 | I12: =IFERROR('Historical FS'!I24/'Historical FS'!H24-1,0) -> 0.28601151 | J12: =IFERROR('Historical FS'!J24/'Historical FS'!I24-1,0) -> 0.11859791 | K12: =IFERROR('Historical FS'!K24/'Historical FS'!J24-1,0) -> 0.0030821215 | L12: =IFERROR('Historical FS'!L24/'Historical FS'!K24-1,0) -> 0.1063874 | N12: =IFERROR(AVERAGE(D12:L12),0) -> 0.12724218 | O12: =IFERROR(MEDIAN(C12:L12),0) -> 0.11249265
